/home/alex/miniconda3/envs/ReinforcementTrader/bin/python /home/alex/PycharmProjects/ReinforcementTrader/START_HERE.py 

üöÄ Starting Revolutionary AI Trading System...
============================================================
‚úì Gunicorn is installed
‚úì Using SQLite database

üåê Starting server on http://127.0.0.1:5000
============================================================

‚ö° The application is starting...
üìä Open your browser to http://127.0.0.1:5000

Press Ctrl+C to stop the server

[2025-07-11 15:33:26 -0700] [30435] [INFO] Starting gunicorn 23.0.0
[2025-07-11 15:33:26 -0700] [30435] [INFO] Listening at: http://127.0.0.1:5000 (30435)
[2025-07-11 15:33:26 -0700] [30435] [INFO] Using worker: sync
[2025-07-11 15:33:26 -0700] [30467] [INFO] Booting worker with pid: 30467
DEBUG:asyncio:Using selector: EpollSelector
INFO:data_manager:Data Manager initialized with data directory: data
INFO:ib_integration:IB Integration initialized
INFO:risk_manager:Risk Manager initialized
INFO:trading_engine:Trading Engine initialized with device: cuda
INFO:trading_engine:Default configurations initialized
INFO:websocket_handler:WebSocket handler initialized
[2025-07-11 15:33:27 -0700] [30467] [ERROR] Exception in worker process
Traceback (most recent call last):
  File "/home/alex/miniconda3/envs/ReinforcementTrader/lib/python3.12/site-packages/sqlalchemy/engine/base.py", line 146, in __init__
    self._dbapi_connection = engine.raw_connection()
                             ^^^^^^^^^^^^^^^^^^^^^^^
  File "/home/alex/miniconda3/envs/ReinforcementTrader/lib/python3.12/site-packages/sqlalchemy/engine/base.py", line 3302, in raw_connection
    return self.pool.connect()
           ^^^^^^^^^^^^^^^^^^^
  File "/home/alex/miniconda3/envs/ReinforcementTrader/lib/python3.12/site-packages/sqlalchemy/pool/base.py", line 449, in connect
    return _ConnectionFairy._checkout(self)
           ^^^^^^^^^^^^^^^^^^^^^^^^^^^^^^^^
  File "/home/alex/miniconda3/envs/ReinforcementTrader/lib/python3.12/site-packages/sqlalchemy/pool/base.py", line 1263, in _checkout
    fairy = _ConnectionRecord.checkout(pool)
            ^^^^^^^^^^^^^^^^^^^^^^^^^^^^^^^^
  File "/home/alex/miniconda3/envs/ReinforcementTrader/lib/python3.12/site-packages/sqlalchemy/pool/base.py", line 712, in checkout
    rec = pool._do_get()
          ^^^^^^^^^^^^^^
  File "/home/alex/miniconda3/envs/ReinforcementTrader/lib/python3.12/site-packages/sqlalchemy/pool/impl.py", line 179, in _do_get
    with util.safe_reraise():
         ^^^^^^^^^^^^^^^^^^^
  File "/home/alex/miniconda3/envs/ReinforcementTrader/lib/python3.12/site-packages/sqlalchemy/util/langhelpers.py", line 146, in __exit__
    raise exc_value.with_traceback(exc_tb)
  File "/home/alex/miniconda3/envs/ReinforcementTrader/lib/python3.12/site-packages/sqlalchemy/pool/impl.py", line 177, in _do_get
    return self._create_connection()
           ^^^^^^^^^^^^^^^^^^^^^^^^^
  File "/home/alex/miniconda3/envs/ReinforcementTrader/lib/python3.12/site-packages/sqlalchemy/pool/base.py", line 390, in _create_connection
    return _ConnectionRecord(self)
           ^^^^^^^^^^^^^^^^^^^^^^^
  File "/home/alex/miniconda3/envs/ReinforcementTrader/lib/python3.12/site-packages/sqlalchemy/pool/base.py", line 674, in __init__
    self.__connect()
  File "/home/alex/miniconda3/envs/ReinforcementTrader/lib/python3.12/site-packages/sqlalchemy/pool/base.py", line 900, in __connect
    with util.safe_reraise():
         ^^^^^^^^^^^^^^^^^^^
  File "/home/alex/miniconda3/envs/ReinforcementTrader/lib/python3.12/site-packages/sqlalchemy/util/langhelpers.py", line 146, in __exit__
    raise exc_value.with_traceback(exc_tb)
  File "/home/alex/miniconda3/envs/ReinforcementTrader/lib/python3.12/site-packages/sqlalchemy/pool/base.py", line 896, in __connect
    self.dbapi_connection = connection = pool._invoke_creator(self)
                                         ^^^^^^^^^^^^^^^^^^^^^^^^^^
  File "/home/alex/miniconda3/envs/ReinforcementTrader/lib/python3.12/site-packages/sqlalchemy/engine/create.py", line 643, in connect
    return dialect.connect(*cargs, **cparams)
           ^^^^^^^^^^^^^^^^^^^^^^^^^^^^^^^^^^
  File "/home/alex/miniconda3/envs/ReinforcementTrader/lib/python3.12/site-packages/sqlalchemy/engine/default.py", line 621, in connect
    return self.loaded_dbapi.connect(*cargs, **cparams)
           ^^^^^^^^^^^^^^^^^^^^^^^^^^^^^^^^^^^^^^^^^^^^
sqlite3.OperationalError: unable to open database file

The above exception was the direct cause of the following exception:

Traceback (most recent call last):
  File "/home/alex/miniconda3/envs/ReinforcementTrader/lib/python3.12/site-packages/gunicorn/arbiter.py", line 608, in spawn_worker
    worker.init_process()
  File "/home/alex/miniconda3/envs/ReinforcementTrader/lib/python3.12/site-packages/gunicorn/workers/base.py", line 135, in init_process
    self.load_wsgi()
  File "/home/alex/miniconda3/envs/ReinforcementTrader/lib/python3.12/site-packages/gunicorn/workers/base.py", line 147, in load_wsgi
    self.wsgi = self.app.wsgi()
                ^^^^^^^^^^^^^^^
  File "/home/alex/miniconda3/envs/ReinforcementTrader/lib/python3.12/site-packages/gunicorn/app/base.py", line 66, in wsgi
    self.callable = self.load()
                    ^^^^^^^^^^^
  File "/home/alex/miniconda3/envs/ReinforcementTrader/lib/python3.12/site-packages/gunicorn/app/wsgiapp.py", line 57, in load
    return self.load_wsgiapp()
           ^^^^^^^^^^^^^^^^^^^
  File "/home/alex/miniconda3/envs/ReinforcementTrader/lib/python3.12/site-packages/gunicorn/app/wsgiapp.py", line 47, in load_wsgiapp
    return util.import_app(self.app_uri)
           ^^^^^^^^^^^^^^^^^^^^^^^^^^^^^
  File "/home/alex/miniconda3/envs/ReinforcementTrader/lib/python3.12/site-packages/gunicorn/util.py", line 370, in import_app
    mod = importlib.import_module(module)
          ^^^^^^^^^^^^^^^^^^^^^^^^^^^^^^^
  File "/home/alex/miniconda3/envs/ReinforcementTrader/lib/python3.12/importlib/__init__.py", line 90, in import_module
    return _bootstrap._gcd_import(name[level:], package, level)
           ^^^^^^^^^^^^^^^^^^^^^^^^^^^^^^^^^^^^^^^^^^^^^^^^^^^^
  File "<frozen importlib._bootstrap>", line 1387, in _gcd_import
  File "<frozen importlib._bootstrap>", line 1360, in _find_and_load
  File "<frozen importlib._bootstrap>", line 1331, in _find_and_load_unlocked
  File "<frozen importlib._bootstrap>", line 935, in _load_unlocked
  File "<frozen importlib._bootstrap_external>", line 999, in exec_module
  File "<frozen importlib._bootstrap>", line 488, in _call_with_frames_removed
  File "/home/alex/PycharmProjects/ReinforcementTrader/main.py", line 1, in <module>
    from app import app
  File "/home/alex/PycharmProjects/ReinforcementTrader/app.py", line 37, in <module>
    db.create_all()
  File "/home/alex/miniconda3/envs/ReinforcementTrader/lib/python3.12/site-packages/flask_sqlalchemy/extension.py", line 900, in create_all
    self._call_for_binds(bind_key, "create_all")
  File "/home/alex/miniconda3/envs/ReinforcementTrader/lib/python3.12/site-packages/flask_sqlalchemy/extension.py", line 881, in _call_for_binds
    getattr(metadata, op_name)(bind=engine)
  File "/home/alex/miniconda3/envs/ReinforcementTrader/lib/python3.12/site-packages/sqlalchemy/sql/schema.py", line 5866, in create_all
    bind._run_ddl_visitor(
  File "/home/alex/miniconda3/envs/ReinforcementTrader/lib/python3.12/site-packages/sqlalchemy/engine/base.py", line 3252, in _run_ddl_visitor
    with self.begin() as conn:
         ^^^^^^^^^^^^
  File "/home/alex/miniconda3/envs/ReinforcementTrader/lib/python3.12/contextlib.py", line 137, in __enter__
    return next(self.gen)
           ^^^^^^^^^^^^^^
  File "/home/alex/miniconda3/envs/ReinforcementTrader/lib/python3.12/site-packages/sqlalchemy/engine/base.py", line 3242, in begin
    with self.connect() as conn:
         ^^^^^^^^^^^^^^
  File "/home/alex/miniconda3/envs/ReinforcementTrader/lib/python3.12/site-packages/sqlalchemy/engine/base.py", line 3278, in connect
    return self._connection_cls(self)
           ^^^^^^^^^^^^^^^^^^^^^^^^^^
  File "/home/alex/miniconda3/envs/ReinforcementTrader/lib/python3.12/site-packages/sqlalchemy/engine/base.py", line 148, in __init__
    Connection._handle_dbapi_exception_noconnection(
  File "/home/alex/miniconda3/envs/ReinforcementTrader/lib/python3.12/site-packages/sqlalchemy/engine/base.py", line 2442, in _handle_dbapi_exception_noconnection
    raise sqlalchemy_exception.with_traceback(exc_info[2]) from e
  File "/home/alex/miniconda3/envs/ReinforcementTrader/lib/python3.12/site-packages/sqlalchemy/engine/base.py", line 146, in __init__
    self._dbapi_connection = engine.raw_connection()
                             ^^^^^^^^^^^^^^^^^^^^^^^
  File "/home/alex/miniconda3/envs/ReinforcementTrader/lib/python3.12/site-packages/sqlalchemy/engine/base.py", line 3302, in raw_connection
    return self.pool.connect()
           ^^^^^^^^^^^^^^^^^^^
  File "/home/alex/miniconda3/envs/ReinforcementTrader/lib/python3.12/site-packages/sqlalchemy/pool/base.py", line 449, in connect
    return _ConnectionFairy._checkout(self)
           ^^^^^^^^^^^^^^^^^^^^^^^^^^^^^^^^
  File "/home/alex/miniconda3/envs/ReinforcementTrader/lib/python3.12/site-packages/sqlalchemy/pool/base.py", line 1263, in _checkout
    fairy = _ConnectionRecord.checkout(pool)
            ^^^^^^^^^^^^^^^^^^^^^^^^^^^^^^^^
  File "/home/alex/miniconda3/envs/ReinforcementTrader/lib/python3.12/site-packages/sqlalchemy/pool/base.py", line 712, in checkout
    rec = pool._do_get()
          ^^^^^^^^^^^^^^
  File "/home/alex/miniconda3/envs/ReinforcementTrader/lib/python3.12/site-packages/sqlalchemy/pool/impl.py", line 179, in _do_get
    with util.safe_reraise():
         ^^^^^^^^^^^^^^^^^^^
  File "/home/alex/miniconda3/envs/ReinforcementTrader/lib/python3.12/site-packages/sqlalchemy/util/langhelpers.py", line 146, in __exit__
    raise exc_value.with_traceback(exc_tb)
  File "/home/alex/miniconda3/envs/ReinforcementTrader/lib/python3.12/site-packages/sqlalchemy/pool/impl.py", line 177, in _do_get
    return self._create_connection()
           ^^^^^^^^^^^^^^^^^^^^^^^^^
  File "/home/alex/miniconda3/envs/ReinforcementTrader/lib/python3.12/site-packages/sqlalchemy/pool/base.py", line 390, in _create_connection
    return _ConnectionRecord(self)
           ^^^^^^^^^^^^^^^^^^^^^^^
  File "/home/alex/miniconda3/envs/ReinforcementTrader/lib/python3.12/site-packages/sqlalchemy/pool/base.py", line 674, in __init__
    self.__connect()
  File "/home/alex/miniconda3/envs/ReinforcementTrader/lib/python3.12/site-packages/sqlalchemy/pool/base.py", line 900, in __connect
    with util.safe_reraise():
         ^^^^^^^^^^^^^^^^^^^
  File "/home/alex/miniconda3/envs/ReinforcementTrader/lib/python3.12/site-packages/sqlalchemy/util/langhelpers.py", line 146, in __exit__
    raise exc_value.with_traceback(exc_tb)
  File "/home/alex/miniconda3/envs/ReinforcementTrader/lib/python3.12/site-packages/sqlalchemy/pool/base.py", line 896, in __connect
    self.dbapi_connection = connection = pool._invoke_creator(self)
                                         ^^^^^^^^^^^^^^^^^^^^^^^^^^
  File "/home/alex/miniconda3/envs/ReinforcementTrader/lib/python3.12/site-packages/sqlalchemy/engine/create.py", line 643, in connect
    return dialect.connect(*cargs, **cparams)
           ^^^^^^^^^^^^^^^^^^^^^^^^^^^^^^^^^^
  File "/home/alex/miniconda3/envs/ReinforcementTrader/lib/python3.12/site-packages/sqlalchemy/engine/default.py", line 621, in connect
    return self.loaded_dbapi.connect(*cargs, **cparams)
           ^^^^^^^^^^^^^^^^^^^^^^^^^^^^^^^^^^^^^^^^^^^^
sqlalchemy.exc.OperationalError: (sqlite3.OperationalError) unable to open database file
(Background on this error at: https://sqlalche.me/e/20/e3q8)
[2025-07-11 15:33:27 -0700] [30467] [INFO] Worker exiting (pid: 30467)
INFO:websocket_handler:Background broadcast thread stopped
[2025-07-11 15:33:28 -0700] [30435] [ERROR] Worker (pid:30467) exited with code 3
[2025-07-11 15:33:28 -0700] [30435] [ERROR] Shutting down: Master
[2025-07-11 15:33:28 -0700] [30435] [ERROR] Reason: Worker failed to boot.

Process finished with exit code 0